<?xml version="1.0"?>
<robot name="myfirst">
<material name="blue">
    <color rgba="0 0 0.8 1"/>
  </material>
  <material name="black">
    <color rgba="0 0 0 1"/>
  </material>
  <material name="white">
    <color rgba="1 1 1 1"/>
  </material>
  
  <!-- base -->
  <link name="base_link">
    <visual>
    <geometry>
        <cylinder length="0.3" radius="0.1"/>
    </geometry>
    <origin rpy="0 0 0" xyz="0 0 0.15"/>
      <material name="blue"/>
    <collision>
      <geometry>
        <cylinder length="0.3" radius="0.1"/>
      </geometry>
      <origin rpy="0 0 0" xyz="0 0 0.15"/>
    </collision>
    </visual>
  </link>
  
<!-- first link -->
  <link name="first_link">
    <visual>
      <geometry>
        <box size="0.3 0.1 0.1"/>
      </geometry>
      <origin rpy="0 1.57075 0" xyz="0 0 0.12"/>
    </visual>
    <collision>
      <geometry>
        <box size="0.2 0.1 0.1"/>
      </geometry>
      <origin rpy="0 1.57075 0" xyz="0 0 0.12"/>
    </collision>
  </link>
  
  <!--first join between ___ -->
  <joint name="base_to_first_link" type="continuous">
    <axis rpy="0 0 0" xyz="0 0 1"/>
    <parent link="base_link"/>
    <child link="first_link"/>
    <origin xyz="0.0 -0.0067 0.3"/>
  </joint>
  
<!-- third link -->
  <link name="second_link">
    <visual>
      <geometry>
        <box size="0.6 0.1 0.1"/>
      </geometry>
      <origin rpy="0 1.57075 0" xyz="0 0 0.30"/>
    </visual>
    <collision>
      <geometry>
        <box size="0.6 0.1 0.1"/>
      </geometry>
      <origin rpy="0 1.57075 0" xyz="0 0 0.30"/>
    </collision>
  </link>

  <joint name="first_link_to_second_link" type="continuous">
    <axis rpy="0 0 0" xyz="0 1 0"/>
    <parent link="first_link"/>
    <child link="second_link"/>
    <origin xyz="0.0 0.1 0.25"/>
  </joint>


<!-- 4 link -->
  <link name="third_link">
    <visual>
      <geometry>
        <box size="0.3 0.1 0.1"/>
      </geometry>
      <origin rpy="0 1.57075 0" xyz="0 0 0.15"/>
    </visual>
    <collision>
      <geometry>
        <box size="0.6 0.1 0.1"/>
      </geometry>
      <origin rpy="0 1.57075 0" xyz="0 0 0.15"/>
    </collision>
  </link>

  <joint name="second_link_to_third_link" type="continuous">
    <axis rpy="0 0 0" xyz="0 1 0"/>
    <parent link="second_link"/>
    <child link="third_link"/>
    <origin xyz="0.0 -0.1 0.55"/>
  </joint>




  
</robot>
